Workbook

Sheet Hypothèses
A1: SIDEBYSIDE — HYPOTHÈSES DE LA PROJECTION FINANCIÈRE (3 ANS)
A2: Cellules en bleu = valeurs modifiables. Tout le reste du classeur recalcule automatiquement.
A4: 1. Contexte de marché (référence — n'entre pas dans les calculs)
A5: Libellé | B5: Valeur | C5: Unité | D5: Source / note
A6: Population agglomération Douala | B6: 4346000 | C6: habitants | D6: Source : macrotrends.net / worldpopulationreview.com, estimation 2025
A7: Population agglomération Yaoundé | B7: 3762900 | C7: habitants | D7: Source : worldpopulationreview.com, estimation 2025
A8: Population agglomération Bafoussam | B8: 496000 | C8: habitants | D8: Source : macrotrends.net, estimation 2025
A9: Comptes mobile money actifs au Cameroun | B9: 25000000 | C9: comptes | D9: Source : GSMA / Investir au Cameroun, 2025 — Cameroun = 62% des comptes actifs CEMAC
A11: 2. Offre — chauffeurs actifs
A12: Libellé | B12: Valeur | C12: Unité | D12: Source / note
A13: Chauffeurs actifs au lancement (mois 1) | B13: 15 | C13: chauffeurs | D13: Hypothèse — phase pilote sur l'axe Douala ↔ Bafoussam
A14: Croissance mensuelle du nb de chauffeurs (mois 1-6) | B14: 0.15 | C14: %/mois | D14: Hypothèse — phase d'acquisition active
A15: Croissance mensuelle du nb de chauffeurs (mois 7-12) | B15: 0.08 | C15: %/mois | D15: Hypothèse — croissance qui se stabilise après la phase de lancement
A16: Croissance mensuelle moyenne du nb de chauffeurs (An 2) | B16: 0.06 | C16: %/mois | D16: Hypothèse — extension à Yaoundé
A17: Croissance mensuelle moyenne du nb de chauffeurs (An 3) | B17: 0.03 | C17: %/mois | D17: Hypothèse — marché en maturité progressive
A19: 3. Activité par chauffeur
A20: Libellé | B20: Valeur | C20: Unité | D20: Source / note
A21: Trajets par chauffeur / mois — mois 1 | B21: 8 | C21: trajets | D21: Hypothèse — début d'activité
A22: Trajets par chauffeur / mois — mois 12 | B22: 18 | C22: trajets | D22: Hypothèse — fidélisation progressive sur l'année 1
A23: Trajets par chauffeur / mois — moyenne An 2 | B23: 20 | C23: trajets | D23: Hypothèse
A24: Trajets par chauffeur / mois — moyenne An 3 | B24: 22 | C24: trajets | D24: Hypothèse
A25: Capacité moyenne par trajet | B25: 4 | C25: places | D25: Cohérent avec des véhicules particuliers (modèle Vehicle du backend)
A26: Taux de remplissage moyen — mois 1 | B26: 0.6 | C26: % | D26: Hypothèse
A27: Taux de remplissage moyen — mois 12 | B27: 0.75 | C27: % | D27: Hypothèse
A28: Taux de remplissage moyen — An 2 | B28: 0.78 | C28: % | D28: Hypothèse
A29: Taux de remplissage moyen — An 3 | B29: 0.8 | C29: % | D29: Hypothèse
A31: 4. Tarifs et panier moyen
A32: Libellé | B32: Valeur | C32: Unité | D32: Source / note
A33: Prix du trajet — Standard | B33: 4500 | C33: FCFA | D33: Source : src/lib/commissionTiers.ts (OFFICIAL_PRICES), axe Douala–Bafoussam
A34: Prix du trajet — Confort | B34: 6500 | C34: FCFA | D34: Source : src/lib/commissionTiers.ts (OFFICIAL_PRICES)
A35: Prix du trajet — Premium VIP | B35: 7500 | C35: FCFA | D35: Source : src/lib/commissionTiers.ts (OFFICIAL_PRICES)
A36: Répartition des réservations — Standard | B36: 0.6 | C36: % | D36: Hypothèse
A37: Répartition des réservations — Confort | B37: 0.3 | C37: % | D37: Hypothèse
A38: Répartition des réservations — Premium VIP | B38: 0.1 | C38: % | D38: Hypothèse
A39: Panier moyen domestique (calculé) | B39: =SUMPRODUCT(B33:B35,B36:B38) -> 5400 | C39: FCFA | D39: Calcul : somme pondérée des 3 tarifs par leur poids dans le mix de réservations
A40: % réservations « cadeau diaspora » — mois 1 | B40: 0.05 | C40: % | D40: Hypothèse
A41: % réservations « cadeau diaspora » — mois 12 | B41: 0.08 | C41: % | D41: Hypothèse
A42: % réservations « cadeau diaspora » — An 2 | B42: 0.1 | C42: % | D42: Hypothèse
A43: % réservations « cadeau diaspora » — An 3 | B43: 0.12 | C43: % | D43: Hypothèse
A44: Multiplicateur panier « cadeau diaspora » vs domestique | B44: 1.8 | C44: x | D44: Hypothèse — paiement en EUR, générosité familiale (mode gift/family)
...

Sheet Mensuel - An 1
A1: SIDEBYSIDE — PROJECTION MENSUELLE, ANNÉE 1
A3: Indicateur | B3: Mois 1 | C3: Mois 2 | D3: Mois 3 | E3: Mois 4 | F3: Mois 5 | G3: Mois 6 | H3: Mois 7 | I3: Mois 8 | J3: Mois 9 | K3: Mois 10 | L3: Mois 11 | M3: Mois 12 | N3: Total / Fin d'année
A4: Chauffeurs actifs (fin de mois) | B4: =Hypothèses!$B$13 -> 15 | C4: =B4*(1+Hypothèses!$B$14) -> 17.25 | D4: =C4*(1+Hypothèses!$B$14) -> 19.8375 | E4: =D4*(1+Hypothèses!$B$14) -> 22.813125 | F4: =E4*(1+Hypothèses!$B$14) -> 26.235094 | G4: =F4*(1+Hypothèses!$B$14) -> 30.170358 | H4: =G4*(1+Hypothèses!$B$15) -> 32.583986 | I4: =H4*(1+Hypothèses!$B$15) -> 35.190705 | J4: =I4*(1+Hypothèses!$B$15) -> 38.005962 | K4: =J4*(1+Hypothèses!$B$15) -> 41.046439 | L4: =K4*(1+Hypothèses!$B$15) -> 44.330154 | M4: =L4*(1+Hypothèses!$B$15) -> 47.876566 | N4: =M4 -> 47.876566
A5: Nouveaux chauffeurs recrutés (mois) | B5: =B4 -> 15 | C5: =C4-B4 -> 2.25 | D5: =D4-C4 -> 2.5875 | E5: =E4-D4 -> 2.975625 | F5: =F4-E4 -> 3.4219688 | G5: =G4-F4 -> 3.9352641 | H5: =H4-G4 -> 2.4136286 | I5: =I4-H4 -> 2.6067189 | J5: =J4-I4 -> 2.8152564 | ... M5: =M4-L4 -> 3.5464123 | N5: =SUM(B5:M5) -> 47.876566
A6: Trajets par chauffeur / mois (moyenne) | B6: =Hypothèses!$B$21+(Hypothèses!$B$22-Hypothèses!$B$21)*(COLUMN()-COLUMN($B$6))/11 -> 8 | C6: =Hypothèses!$B$21+(Hypothèses!$B$22-Hypothèses!$B$21)*(COLUMN()-COLUMN($B$6))/11 -> 8.9090909 | D6: =Hypothèses!$B$21+(Hypothèses!$B$22-Hypothèses!$B$21)*(COLUMN()-COLUMN($B$6))/11 -> 9.8181818 | E6: =Hypothèses!$B$21+(Hypothèses!$B$22-Hypothèses!$B$21)*(COLUMN()-COLUMN($B$6))/11 -> 10.727273 | F6: =Hypothèses!$B$21+(Hypothèses!$B$22-Hypothèses!$B$21)*(COLUMN()-COLUMN($B$6))/11 -> 11.636364 | G6: =Hypothèses!$B$21+(Hypothèses!$B$22-Hypothèses!$B$21)*(COLUMN()-COLUMN($B$6))/11 -> 12.545455 | H6: =Hypothèses!$B$21+(Hypothèses!$B$22-Hypothèses!$B$21)*(COLUMN()-COLUMN($B$6))/11 -> 13.454545 | I6: =Hypothèses!$B$21+(Hypothèses!$B$22-Hypothèses!$B$21)*(COLUMN()-COLUMN($B$6))/11 -> 14.363636 | ... M6: =Hypothèses!$B$21+(Hypothèses!$B$22-Hypothèses!$B$21)*(COLUMN()-COLUMN($B$6))/11 -> 18 | N6: =M6 -> 18
A7: Trajets publiés (total) | B7: =B4*B6 -> 120 | C7: =C4*C6 -> 153.68182 | D7: =D4*D6 -> 194.76818 | E7: =E4*E6 -> 244.72261 | F7: =F4*F6 -> 305.28109 | G7: =G4*G6 -> 378.50085 | H7: =H4*H6 -> 438.40273 | I7: =I4*I6 -> 505.4665 | ... M7: =M4*M6 -> 861.77819 | N7: =SUM(B7:M7) -> 5204.9053
A8: Taux de remplissage moyen | B8: =Hypothèses!$B$26+(Hypothèses!$B$27-Hypothèses!$B$26)*(COLUMN()-COLUMN($B$8))/11 -> 0.6 | C8: =Hypothèses!$B$26+(Hypothèses!$B$27-Hypothèses!$B$26)*(COLUMN()-COLUMN($B$8))/11 -> 0.61363636 | D8: =Hypothèses!$B$26+(Hypothèses!$B$27-Hypothèses!$B$26)*(COLUMN()-COLUMN($B$8))/11 -> 0.62727273 | E8: =Hypothèses!$B$26+(Hypothèses!$B$27-Hypothèses!$B$26)*(COLUMN()-COLUMN($B$8))/11 -> 0.64090909 | F8: =Hypothèses!$B$26+(Hypothèses!$B$27-Hypothèses!$B$26)*(COLUMN()-COLUMN($B$8))/11 -> 0.65454545 | G8: =Hypothèses!$B$26+(Hypothèses!$B$27-Hypothèses!$B$26)*(COLUMN()-COLUMN($B$8))/11 -> 0.66818182 | H8: =Hypothèses!$B$26+(Hypothèses!$B$27-Hypothèses!$B$26)*(COLUMN()-COLUMN($B$8))/11 -> 0.68181818 | I8: =Hypothèses!$B$26+(Hypothèses!$B$27-Hypothèses!$B$26)*(COLUMN()-COLUMN($B$8))/11 -> 0.69545455 | ... M8: =Hypothèses!$B$26+(Hypothèses!$B$27-Hypothèses!$B$26)*(COLUMN()-COLUMN($B$8))/11 -> 0.75 | N8: =M8 -> 0.75
A9: Places vendues par trajet | B9: =Hypothèses!$B$25*B8 -> 2.4 | C9: =Hypothèses!$B$25*C8 -> 2.4545455 | D9: =Hypothèses!$B$25*D8 -> 2.5090909 | E9: =Hypothèses!$B$25*E8 -> 2.5636364 | F9: =Hypothèses!$B$25*F8 -> 2.6181818 | G9: =Hypothèses!$B$25*G8 -> 2.6727273 | H9: =Hypothèses!$B$25*H8 -> 2.7272727 | I9: =Hypothèses!$B$25*I8 -> 2.7818182 | ... M9: =Hypothèses!$B$25*M8 -> 3 | N9: =M9 -> 3
A10: Réservations totales (places réservées) | B10: =B7*B9 -> 288 | C10: =C7*C9 -> 377.21901 | D10: =D7*D9 -> 488.69107 | E10: =E7*E9 -> 627.37979 | F10: =F7*F9 -> 799.2814 | G10: =G7*G9 -> 1011.6296 | H10: =H7*H9 -> 1195.6438 | I10: =I7*I9 -> 1406.1159 | ... M10: =M7*M9 -> 2585.3346 | N10: =SUM(B10:M10) -> 14577.437
A11: % réservations « cadeau diaspora » | B11: =Hypothèses!$B$40+(Hypothèses!$B$41-Hypothèses!$B$40)*(COLUMN()-COLUMN($B$11))/11 -> 0.05 | C11: =Hypothèses!$B$40+(Hypothèses!$B$41-Hypothèses!$B$40)*(COLUMN()-COLUMN($B$11))/11 -> 0.052727273 | D11: =Hypothèses!$B$40+(Hypothèses!$B$41-Hypothèses!$B$40)*(COLUMN()-COLUMN($B$11))/11 -> 0.055454545 | E11: =Hypothèses!$B$40+(Hypothèses!$B$41-Hypothèses!$B$40)*(COLUMN()-COLUMN($B$11))/11 -> 0.058181818 | F11: =Hypothèses!$B$40+(Hypothèses!$B$41-Hypothèses!$B$40)*(COLUMN()-COLUMN($B$11))/11 -> 0.060909091 | G11: =Hypothèses!$B$40+(Hypothèses!$B$41-Hypothèses!$B$40)*(COLUMN()-COLUMN($B$11))/11 -> 0.063636364 | H11: =Hypothèses!$B$40+(Hypothèses!$B$41-Hypothèses!$B$40)*(COLUMN()-COLUMN($B$11))/11 -> 0.066363636 | I11: =Hypothèses!$B$40+(Hypothèses!$B$41-Hypothèses!$B$40)*(COLUMN()-COLUMN($B$11))/11 -> 0.069090909 | ... M11: =Hypothèses!$B$40+(Hypothèses!$B$41-Hypothèses!$B$40)*(COLUMN()-COLUMN($B$11))/11 -> 0.08 | N11: =M11 -> 0.08
A12: Réservations domestiques | B12: =B10*(1-B11) -> 273.6 | C12: =C10*(1-C11) -> 357.32928 | D12: =D10*(1-D11) -> 461.59093 | E12: =E10*(1-E11) -> 590.87769 | F12: =F10*(1-F11) -> 750.5979 | G12: =G10*(1-G11) -> 947.25313 | H12: =H10*(1-H11) -> 1116.2965 | I12: =I10*(1-I11) -> 1308.9661 | ... M12: =M10*(1-M11) -> 2378.5078 | N12: =SUM(B12:M12) -> 13549.34
A13: Réservations « cadeau diaspora » | B13: =B10*B11 -> 14.4 | C13: =C10*C11 -> 19.88973 | D13: =D10*D11 -> 27.100141 | E13: =E10*E11 -> 36.502097 | F13: =F10*F11 -> 48.683504 | G13: =G10*G11 -> 64.376426 | H13: =H10*H11 -> 79.34727 | I13: =I10*I11 -> 97.149825 | ... M13: =M10*M11 -> 206.82677 | N13: =SUM(B13:M13) -> 1028.0969
A14: Panier moyen domestique | B14: =Hypothèses!$B$39 -> 5400 | C14: =Hypothèses!$B$39 -> 5400 | D14: =Hypothèses!$B$39 -> 5400 | E14: =Hypothèses!$B$39 -> 5400 | F14: =Hypothèses!$B$39 -> 5400 | G14: =Hypothèses!$B$39 -> 5400 | H14: =Hypothèses!$B$39 -> 5400 | I14: =Hypothèses!$B$39 -> 5400 | ... M14: =Hypothèses!$B$39 -> 5400 | N14: =M14 -> 5400
A15: Panier moyen « cadeau diaspora » | B15: =B14*Hypothèses!$B$44 -> 9720 | C15: =C14*Hypothèses!$B$44 -> 9720 | D15: =D14*Hypothèses!$B$44 -> 9720 | E15: =E14*Hypothèses!$B$44 -> 9720 | F15: =F14*Hypothèses!$B$44 -> 9720 | G15: =G14*Hypothèses!$B$44 -> 9720 | H15: =H14*Hypothèses!$B$44 -> 9720 | I15: =I14*Hypothèses!$B$44 -> 9720 | ... M15: =M14*Hypothèses!$B$44 -> 9720 | N15: =M15 -> 9720
A16: GMV domestique | B16: =B12*B14 -> 1477440 | C16: =C12*C14 -> 1929578.1 | D16: =D12*D14 -> 2492591 | E16: =E12*E14 -> 3190739.5 | F16: =F12*F14 -> 4053228.6 | G16: =G12*G14 -> 5115166.9 | H16: =H12*H14 -> 6028001.3 | I16: =I12*I14 -> 7068416.7 | ... M16: =M12*M14 -> 12843942 | N16: =SUM(B16:M16) -> 73166435
A17: GMV « cadeau diaspora » | B17: =B13*B15 -> 139968 | C17: =C13*C15 -> 193328.17 | D17: =D13*D15 -> 263413.37 | E17: =E13*E15 -> 354800.38 | F17: =F13*F15 -> 473203.65 | G17: =G13*G15 -> 625738.86 | H17: =H13*H15 -> 771255.47 | I17: =I13*I15 -> 944296.3 | ... M17: =M13*M15 -> 2010356.2 | N17: =SUM(B17:M17) -> 9993102.1
A18: GMV total | B18: =B16+B17 -> 1617408 | C18: =C16+C17 -> 2122906.3 | D18: =D16+D17 -> 2756004.4 | E18: =E16+E17 -> 3545539.9 | F18: =F16+F17 -> 4526432.3 | G18: =G16+G17 -> 5740905.7 | H18: =H16+H17 -> 6799256.7 | I18: =I16+I17 -> 8012713 | ... M18: =M16+M17 -> 14854298 | N18: =SUM(B18:M18) -> 83159537
A19: Taux de commission moyen | B19: =Hypothèses!$B$51 -> 0.14 | C19: =Hypothèses!$B$51 -> 0.14 | D19: =Hypothèses!$B$51 -> 0.14 | E19: =Hypothèses!$B$51 -> 0.14 | F19: =Hypothèses!$B$51 -> 0.14 | G19: =Hypothèses!$B$51 -> 0.14 | H19: =Hypothèses!$B$51 -> 0.14 | I19: =Hypothèses!$B$51 -> 0.14 | ... M19: =Hypothèses!$B$51 -> 0.14 | N19: =M19 -> 0.14
A20: Revenu commission (brut) | B20: =B18*B19 -> 226437.12 | C20: =C18*C19 -> 297206.88 | D20: =D18*D19 -> 385840.62 | E20: =E18*E19 -> 496375.59 | F20: =F18*F19 -> 633700.52 | G20: =G18*G19 -> 803726.8 | H20: =H18*H19 -> 951895.94 | I20: =I18*I19 -> 1121779.8 | ... M20: =M18*M19 -> 2079601.8 | N20: =SUM(B20:M20) -> 11642335
A21: % réservations payées en mobile money | B21: =Hypothèses!$B$54+(Hypothèses!$B$55-Hypothèses!$B$54)*(COLUMN()-COLUMN($B$21))/11 -> 0.7 | C21: =Hypothèses!$B$54+(Hypothèses!$B$55-Hypothèses!$B$54)*(COLUMN()-COLUMN($B$21))/11 -> 0.70909091 | D21: =Hypothèses!$B$54+(Hypothèses!$B$55-Hypothèses!$B$54)*(COLUMN()-COLUMN($B$21))/11 -> 0.71818182 | E21: =Hypothèses!$B$54+(Hypothèses!$B$55-Hypothèses!$B$54)*(COLUMN()-COLUMN($B$21))/11 -> 0.72727273 | F21: =Hypothèses!$B$54+(Hypothèses!$B$55-Hypothèses!$B$54)*(COLUMN()-COLUMN($B$21))/11 -> 0.73636364 | G21: =Hypothèses!$B$54+(Hypothèses!$B$55-Hypothèses!$B$54)*(COLUMN()-COLUMN($B$21))/11 -> 0.74545455 | H21: =Hypothèses!$B$54+(Hypothèses!$B$55-Hypothèses!$B$54)*(COLUMN()-COLUMN($B$21))/11 -> 0.75454545 | I21: =Hypothèses!$B$54+(Hypothèses!$B$55-Hypothèses!$B$54)*(COLUMN()-COLUMN($B$21))/11 -> 0.76363636 | ... M21: =Hypothèses!$B$54+(Hypothèses!$B$55-Hypothèses!$B$54)*(COLUMN()-COLUMN($B$21))/11 -> 0.8 | N21: =M21 -> 0.8
A22: Réservations payées en digital | B22: =B10*B21 -> 201.6 | C22: =C10*C21 -> 267.48257 | D22: =D10*D21 -> 350.96904 | E22: =E10*E21 -> 456.27621 | F22: =F10*F21 -> 588.56176 | G22: =G10*G21 -> 754.12385 | H22: =H10*H21 -> 902.16759 | I22: =I10*I21 -> 1073.7612 | ... M22: =M10*M21 -> 2068.2677 | N22: =SUM(B22:M22) -> 11201.623
A23: Coûts variables
A24: Remise incitation paiement digital | B24: =B22*Hypothèses!$B$57 -> 40320 | C24: =C22*Hypothèses!$B$57 -> 53496.514 | D24: =D22*Hypothèses!$B$57 -> 70193.809 | E24: =E22*Hypothèses!$B$57 -> 91255.242 | F24: =F22*Hypothèses!$B$57 -> 117712.35 | G24: =G22*Hypothèses!$B$57 -> 150824.77 | H24: =H22*Hypothèses!$B$57 -> 180433.52 | I24: =I22*Hypothèses!$B$57 -> 214752.24 | ... M24: =M22*Hypothèses!$B$57 -> 413653.53 | N24: =SUM(B24:M24) -> 2240324.5
A25: Frais de passerelle de paiement | B25: =B18*B21*Hypothèses!$B$58 -> 20379.341 | C25: =C18*C21*Hypothèses!$B$58 -> 27096.004 | D25: =D18*D21*Hypothèses!$B$58 -> 35627.621 | E25: =E18*E21*Hypothèses!$B$58 -> 46414.341 | F25: =F18*F21*Hypothèses!$B$58 -> 59995.803 | G25: =G18*G21*Hypothèses!$B$58 -> 77032.517 | H25: =H18*H21*Hypothèses!$B$58 -> 92346.269 | I25: =I18*I21*Hypothèses!$B$58 -> 110138.38 | ... M25: =M18*M21*Hypothèses!$B$58 -> 213901.9 | N25: =SUM(B25:M25) -> 1150478
A26: Coût vérification KYC (nouveaux chauffeurs) | B26: =B5*Hypothèses!$B$59 -> 7500 | C26: =C5*Hypothèses!$B$59 -> 1125 | D26: =D5*Hypothèses!$B$59 -> 1293.75 | E26: =E5*Hypothèses!$B$59 -> 1487.8125 | F26: =F5*Hypothèses!$B$59 -> 1710.9844 | G26: =G5*Hypothèses!$B$59 -> 1967.632 | H26: =H5*Hypothèses!$B$59 -> 1206.8143 | I26: =I5*Hypothèses!$B$59 -> 1303.3595 | ... M26: =M5*Hypothèses!$B$59 -> 1773.2062 | N26: =SUM(B26:M26) -> 23938.283
A27: Coûts variables totaux | B27: =B24+B25+B26 -> 68199.341 | C27: =C24+C25+C26 -> 81717.518 | D27: =D24+D25+D26 -> 107115.18 | E27: =E24+E25+E26 -> 139157.4 | F27: =F24+F25+F26 -> 179419.14 | G27: =G24+G25+G26 -> 229824.92 | H27: =H24+H25+H26 -> 273986.6 | I27: =I24+I25+I26 -> 326193.99 | ... M27: =M24+M25+M26 -> 629328.63 | N27: =SUM(B27:M27) -> 3414740.8
A28: Marge brute | B28: =B20-B27 -> 158237.78 | C28: =C20-C27 -> 215489.36 | D28: =D20-D27 -> 278725.44 | E28: =E20-E27 -> 357218.19 | F28: =F20-F27 -> 454281.38 | G28: =G20-G27 -> 573901.88 | H28: =H20-H27 -> 677909.34 | I28: =I20-I27 -> 795585.84 | ... M28: =M20-M27 -> 1450273.1 | N28: =SUM(B28:M28) -> 8227594.4
A29: Coûts fixes (Opex)
A30: Infra & hébergement | B30: =Hypothèses!$B$63*(1+Hypothèses!$B$64)^(COLUMN()-COLUMN($B$30)) -> 40000 | C30: =Hypothèses!$B$63*(1+Hypothèses!$B$64)^(COLUMN()-COLUMN($B$30)) -> 41200 | D30: =Hypothèses!$B$63*(1+Hypothèses!$B$64)^(COLUMN()-COLUMN($B$30)) -> 42436 | E30: =Hypothèses!$B$63*(1+Hypothèses!$B$64)^(COLUMN()-COLUMN($B$30)) -> 43709.08 | F30: =Hypothèses!$B$63*(1+Hypothèses!$B$64)^(COLUMN()-COLUMN($B$30)) -> 45020.352 | G30: =Hypothèses!$B$63*(1+Hypothèses!$B$64)^(COLUMN()-COLUMN($B$30)) -> 46370.963 | H30: =Hypothèses!$B$63*(1+Hypothèses!$B$64)^(COLUMN()-COLUMN($B$30)) -> 47762.092 | I30: =Hypothèses!$B$63*(1+Hypothèses!$B$64)^(COLUMN()-COLUMN($B$30)) -> 49194.955 | ... M30: =Hypothèses!$B$63*(1+Hypothèses!$B$64)^(COLUMN()-COLUMN($B$30)) -> 55369.355 | N30: =SUM(B30:M30) -> 567681.18
A31: Effectif salarié | B31: =IF(COLUMN()-COLUMN($B$31)<=5,Hypothèses!$B$67,Hypothèses!$B$68) -> 0 | C31: =IF(COLUMN()-COLUMN($B$31)<=5,Hypothèses!$B$67,Hypothèses!$B$68) -> 0 | D31: =IF(COLUMN()-COLUMN($B$31)<=5,Hypothèses!$B$67,Hypothèses!$B$68) -> 0 | E31: =IF(COLUMN()-COLUMN($B$31)<=5,Hypothèses!$B$67,Hypothèses!$B$68) -> 0 | F31: =IF(COLUMN()-COLUMN($B$31)<=5,Hypothèses!$B$67,Hypothèses!$B$68) -> 0 | G31: =IF(COLUMN()-COLUMN($B$31)<=5,Hypothèses!$B$67,Hypothèses!$B$68) -> 0 | H31: =IF(COLUMN()-COLUMN($B$31)<=5,Hypothèses!$B$67,Hypothèses!$B$68) -> 1 | I31: =IF(COLUMN()-COLUMN($B$31)<=5,Hypothèses!$B$67,Hypothèses!$B$68) -> 1 | ... M31: =IF(COLUMN()-COLUMN($B$31)<=5,Hypothèses!$B$67,Hypothèses!$B$68) -> 1 | N31: =M31 -> 1
A32: Masse salariale | B32: =B31*Hypothèses!$B$71 -> 0 | C32: =C31*Hypothèses!$B$71 -> 0 | D32: =D31*Hypothèses!$B$71 -> 0 | E32: =E31*Hypothèses!$B$71 -> 0 | F32: =F31*Hypothèses!$B$71 -> 0 | G32: =G31*Hypothèses!$B$71 -> 0 | H32: =H31*Hypothèses!$B$71 -> 250000 | I32: =I31*Hypothèses!$B$71 -> 250000 | ... M32: =M31*Hypothèses!$B$71 -> 250000 | N32: =SUM(B32:M32) -> 1500000
A33: Marketing & acquisition | B33: =Hypothèses!$B$72*(1+Hypothèses!$B$73)^(COLUMN()-COLUMN($B$33)) -> 100000 | C33: =Hypothèses!$B$72*(1+Hypothèses!$B$73)^(COLUMN()-COLUMN($B$33)) -> 105000 | D33: =Hypothèses!$B$72*(1+Hypothèses!$B$73)^(COLUMN()-COLUMN($B$33)) -> 110250 | E33: =Hypothèses!$B$72*(1+Hypothèses!$B$73)^(COLUMN()-COLUMN($B$33)) -> 115762.5 | F33: =Hypothèses!$B$72*(1+Hypothèses!$B$73)^(COLUMN()-COLUMN($B$33)) -> 121550.62 | G33: =Hypothèses!$B$72*(1+Hypothèses!$B$73)^(COLUMN()-COLUMN($B$33)) -> 127628.16 | H33: =Hypothèses!$B$72*(1+Hypothèses!$B$73)^(COLUMN()-COLUMN($B$33)) -> 134009.56 | I33: =Hypothèses!$B$72*(1+Hypothèses!$B$73)^(COLUMN()-COLUMN($B$33)) -> 140710.04 | ... M33: =Hypothèses!$B$72*(1+Hypothèses!$B$73)^(COLUMN()-COLUMN($B$33)) -> 171033.94 | N33: =SUM(B33:M33) -> 1591712.7
A34: Frais généraux & légal | B34: =Hypothèses!$B$76 -> 60000 | C34: =Hypothèses!$B$76 -> 60000 | D34: =Hypothèses!$B$76 -> 60000 | E34: =Hypothèses!$B$76 -> 60000 | F34: =Hypothèses!$B$76 -> 60000 | G34: =Hypothèses!$B$76 -> 60000 | H34: =Hypothèses!$B$76 -> 60000 | I34: =Hypothèses!$B$76 -> 60000 | ... M34: =Hypothèses!$B$76 -> 60000 | N34: =SUM(B34:M34) -> 720000
A35: Coûts fixes totaux | B35: =B30+B32+B33+B34 -> 200000 | C35: =C30+C32+C33+C34 -> 206200 | D35: =D30+D32+D33+D34 -> 212686 | E35: =E30+E32+E33+E34 -> 219471.58 | F35: =F30+F32+F33+F34 -> 226570.98 | G35: =G30+G32+G33+G34 -> 233999.12 | H35: =H30+H32+H33+H34 -> 491771.66 | I35: =I30+I32+I33+I34 -> 499905 | ... M35: =M30+M32+M33+M34 -> 536403.29 | N35: =SUM(B35:M35) -> 4379393.8
A36: Résultat
A37: EBITDA (résultat opérationnel) | B37: =B28-B35 -> -41762.221 | C37: =C28-C35 -> 9289.361 | D37: =D28-D35 -> 66039.438 | E37: =E28-E35 -> 137746.61 | F37: =F28-F35 -> 227710.41 | G37: =G28-G35 -> 339902.77 | H37: =H28-H35 -> 186137.68 | I37: =I28-I35 -> 295680.84 | ... M37: =M28-M35 -> 913869.84 | N37: =SUM(B37:M37) -> 3848200.5
A38: EBITDA cumulé (trésorerie opérationnelle) | B38: =B37 -> -41762.221 | C38: =B38+C37 -> -32472.86 | D38: =C38+D37 -> 33566.578 | E38: =D38+E37 -> 171313.19 | F38: =E38+F37 -> 399023.6 | G38: =F38+G37 -> 738926.36 | H38: =G38+H37 -> 925064.05 | I38: =H38+I37 -> 1220744.9 | J38: =I38+J37 -> 1641892.7 | ... M38: =L38+M37 -> 3848200.5 | N38: =M38 -> 3848200.5

Sheet Annuel - An 1 à 3
A1: SIDEBYSIDE — PROJECTION ANNUELLE, ANNÉES 1 À 3
A3: Indicateur | B3: Année 1 | C3: Année 2 | D3: Année 3
A4: Chauffeurs actifs — début d'année | B4: =Hypothèses!$B$13 -> 15 | C4: =B5 -> 47.876566 | D4: =C5 -> 96.337057
A5: Chauffeurs actifs — fin d'année | B5: ='Mensuel - An 1'!$M$4 -> 47.876566 | C5: =B5*(1+Hypothèses!$B$16)^12 -> 96.337057 | D5: =C5*(1+Hypothèses!$B$17)^12 -> 137.35361
A6: Chauffeurs actifs — moyenne | B6: =(B4+B5)/2 -> 31.438283 | C6: =(C4+C5)/2 -> 72.106812 | D6: =(D4+D5)/2 -> 116.84533
A7: Trajets par chauffeur / mois (moyenne) | B7: =AVERAGE('Mensuel - An 1'!B6:M6) -> 13 | C7: =Hypothèses!$B$23 -> 20 | D7: =Hypothèses!$B$24 -> 22
A8: Trajets publiés (total année) | B8: =SUM('Mensuel - An 1'!B7:M7) -> 5204.9053 | C8: =C6*C7*12 -> 17305.635 | D8: =D6*D7*12 -> 30847.168
A9: Taux de remplissage moyen | B9: =AVERAGE('Mensuel - An 1'!B8:M8) -> 0.675 | C9: =Hypothèses!$B$28 -> 0.78 | D9: =Hypothèses!$B$29 -> 0.8
A10: Places vendues par trajet | B10: =Hypothèses!$B$25*B9 -> 2.7 | C10: =Hypothèses!$B$25*C9 -> 3.12 | D10: =Hypothèses!$B$25*D9 -> 3.2
A11: Réservations totales (places réservées) | B11: =SUM('Mensuel - An 1'!B10:M10) -> 14577.437 | C11: =C8*C10 -> 53993.581 | D11: =D8*D10 -> 98710.937
A12: % réservations « cadeau diaspora » | B12: =AVERAGE('Mensuel - An 1'!B11:M11) -> 0.065 | C12: =Hypothèses!$B$42 -> 0.1 | D12: =Hypothèses!$B$43 -> 0.12
A13: Réservations domestiques | B13: =SUM('Mensuel - An 1'!B12:M12) -> 13549.34 | C13: =C11*(1-C12) -> 48594.223 | D13: =D11*(1-D12) -> 86865.625
A14: Réservations « cadeau diaspora » | B14: =SUM('Mensuel - An 1'!B13:M13) -> 1028.0969 | C14: =C11*C12 -> 5399.3581 | D14: =D11*D12 -> 11845.312
A15: Panier moyen domestique | B15: =Hypothèses!$B$39 -> 5400 | C15: =Hypothèses!$B$39 -> 5400 | D15: =Hypothèses!$B$39 -> 5400
A16: Panier moyen « cadeau diaspora » | B16: =B15*Hypothèses!$B$44 -> 9720 | C16: =C15*Hypothèses!$B$44 -> 9720 | D16: =D15*Hypothèses!$B$44 -> 9720
A17: GMV domestique | B17: =SUM('Mensuel - An 1'!B16:M16) -> 73166435 | C17: =C13*C15 -> 2.624088e+08 | D17: =D13*D15 -> 4.6907437e+08
A18: GMV « cadeau diaspora » | B18: =SUM('Mensuel - An 1'!B17:M17) -> 9993102.1 | C18: =C14*C16 -> 52481760 | D18: =D14*D16 -> 1.1513644e+08
A19: GMV total | B19: =B17+B18 -> 83159537 | C19: =C17+C18 -> 3.1489056e+08 | D19: =D17+D18 -> 5.8421081e+08
A20: Taux de commission moyen | B20: =Hypothèses!$B$51 -> 0.14 | C20: =Hypothèses!$B$52 -> 0.125 | D20: =Hypothèses!$B$53 -> 0.115
A21: Revenu commission (brut) | B21: =SUM('Mensuel - An 1'!B20:M20) -> 11642335 | C21: =C19*C20 -> 39361320 | D21: =D19*D20 -> 67184243
A22: % réservations payées en mobile money | B22: =AVERAGE('Mensuel - An 1'!B21:M21) -> 0.75 | C22: =Hypothèses!$B$56 -> 0.85 | D22: =Hypothèses!$B$56 -> 0.85
A23: Coûts variables
A24: Remise incitation paiement digital | B24: =SUM('Mensuel - An 1'!B24:M24) -> 2240324.5 | C24: =C11*C22*Hypothèses!$B$57 -> 9178908.7 | D24: =D11*D22*Hypothèses!$B$57 -> 16780859
A25: Frais de passerelle de paiement | B25: =SUM('Mensuel - An 1'!B25:M25) -> 1150478 | C25: =C19*C22*Hypothèses!$B$58 -> 4817825.6 | D25: =D19*D22*Hypothèses!$B$58 -> 8938425.4
A26: Nouveaux chauffeurs (année) | B26: =SUM('Mensuel - An 1'!B5:M5) -> 47.876566 | C26: =C5-B5 -> 48.460491 | D26: =D5-C5 -> 41.016551
A27: Coût vérification KYC (nouveaux chauffeurs) | B27: =B26*Hypothèses!$B$59 -> 23938.283 | C27: =C26*Hypothèses!$B$59 -> 24230.246 | D27: =D26*Hypothèses!$B$59 -> 20508.276
A28: Coûts variables totaux | B28: =B24+B25+B27 -> 3414740.8 | C28: =C24+C25+C27 -> 14020965 | D28: =D24+D25+D27 -> 25739793
A29: Marge brute | B29: =B21-B28 -> 8227594.4 | C29: =C21-C28 -> 25340356 | D29: =D21-D28 -> 41444450
A30: Coûts fixes (Opex)
A31: Effectif salarié (moyenne) | B31: =AVERAGE('Mensuel - An 1'!B31:M31) -> 0.5 | C31: =Hypothèses!$B$69 -> 3 | D31: =Hypothèses!$B$70 -> 6
A32: Infra & hébergement (année) | B32: =SUM('Mensuel - An 1'!B30:M30) -> 567681.18 | C32: =Hypothèses!$B$65 -> 900000 | D32: =Hypothèses!$B$66 -> 1800000
A33: Masse salariale (année) | B33: =SUM('Mensuel - An 1'!B32:M32) -> 1500000 | C33: =C31*Hypothèses!$B$71*12 -> 9000000 | D33: =D31*Hypothèses!$B$71*12 -> 18000000
A34: Marketing & acquisition (année) | B34: =SUM('Mensuel - An 1'!B33:M33) -> 1591712.7 | C34: =Hypothèses!$B$74 -> 3000000 | D34: =Hypothèses!$B$75 -> 6000000
A35: Frais généraux & légal (année) | B35: =SUM('Mensuel - An 1'!B34:M34) -> 720000 | C35: =Hypothèses!$B$77*12 -> 1800000 | D35: =Hypothèses!$B$78*12 -> 3600000
A36: Coûts fixes totaux | B36: =B32+B33+B34+B35 -> 4379393.8 | C36: =C32+C33+C34+C35 -> 14700000 | D36: =D32+D33+D34+D35 -> 29400000
A37: Résultat
A38: EBITDA (résultat opérationnel) | B38: =B29-B36 -> 3848200.5 | C38: =C29-C36 -> 10640356 | D38: =D29-D36 -> 12044450
A39: Marge EBITDA (% du revenu commission) | B39: =B38/B21 -> 0.33053511 | C39: =C38/C21 -> 0.27032517 | D39: =D38/D21 -> 0.17927493
A40: Trésorerie opérationnelle cumulée (fin d'année) | B40: ='Mensuel - An 1'!$M$38 -> 3848200.5 | C40: =B40+C38 -> 14488556 | D40: =C40+D38 -> 26533007

Sheet Scénarios
A1: SIDEBYSIDE — SCÉNARIO PESSIMISTE VS BASE (ANNÉE 1)
A2: Cellules en bleu = dégradations modifiables vs le scénario de base. Le reste recalcule automatiquement.
A4: Hypothèses de dégradation (vs scénario de base, Année 1)
A5: Chauffeurs actifs fin d'année (variation) | B5: -0.3 | E5: Churn plus élevé que prévu : moins de chauffeurs retenus sur la durée
A6: Trajets / chauffeur / mois (variation) | B6: -0.1 | E6: Chauffeurs restants moins actifs / moins fidélisés
A7: Taux de remplissage moyen (variation) | B7: -0.15 | E7: Demande passagers plus faible que prévu
A8: Adoption « cadeau diaspora » (variation) | B8: -0.5 | E8: Canal diaspora plus lent à démarrer (confiance, acquisition à l'étranger)
A9: Budget marketing (variation) | B9: 0.2 | E9: Effort supplémentaire supposé pour contrer le churn chauffeurs/passagers
A11: Indicateur (Année 1) | B11: Base | C11: Pessimiste | D11: Écart | E11: Commentaire
A12: Chauffeurs actifs — fin d'année | B12: ='Annuel - An 1 à 3'!B5 -> 47.876566 | C12: =B12*(1+$B$5) -> 33.513596 | D12: =C12-B12 -> -14.36297
A13: Chauffeurs actifs — moyenne | B13: ='Annuel - An 1 à 3'!B6 -> 31.438283 | C13: =('Annuel - An 1 à 3'!$B$4+C12)/2 -> 24.256798 | D13: =C13-B13 -> -7.1814849
A14: Trajets par chauffeur / mois (moyenne) | B14: ='Annuel - An 1 à 3'!B7 -> 13 | C14: =B14*(1+$B$6) -> 11.7 | D14: =C14-B14 -> -1.3
A15: Trajets publiés (total année) | B15: ='Annuel - An 1 à 3'!B8 -> 5204.9053 | C15: =C13*C14*12 -> 3405.6545 | D15: =C15-B15 -> -1799.2508
A16: Taux de remplissage moyen | B16: ='Annuel - An 1 à 3'!B9 -> 0.675 | C16: =B16*(1+$B$7) -> 0.57375 | D16: =C16-B16 -> -0.10125
A17: Places vendues par trajet | B17: ='Annuel - An 1 à 3'!B10 -> 2.7 | C17: =Hypothèses!$B$25*C16 -> 2.295 | D17: =C17-B17 -> -0.405
A18: Réservations totales (places réservées) | B18: ='Annuel - An 1 à 3'!B11 -> 14577.437 | C18: =C15*C17 -> 7815.977 | D18: =C18-B18 -> -6761.4598
A19: % réservations « cadeau diaspora » | B19: ='Annuel - An 1 à 3'!B12 -> 0.065 | C19: =B19*(1+$B$8) -> 0.0325 | D19: =C19-B19 -> -0.0325
A20: GMV total | B20: ='Annuel - An 1 à 3'!B19 -> 83159537 | C20: =C18*((1-C19)*'Annuel - An 1 à 3'!$B$15+C19*'Annuel - An 1 à 3'!$B$16) -> 43303639 | D20: =C20-B20 -> -39855898
A21: Revenu commission (brut) | B21: ='Annuel - An 1 à 3'!B21 -> 11642335 | C21: =C20*'Annuel - An 1 à 3'!$B$20 -> 6062509.4 | D21: =C21-B21 -> -5579825.8
A22: Coûts variables totaux | B22: ='Annuel - An 1 à 3'!B28 -> 3414740.8 | C22: =C18*'Annuel - An 1 à 3'!$B$22*Hypothèses!$B$57+C20*'Annuel - An 1 à 3'!$B$22*Hypothèses!$B$58+'Annuel - An 1 à 3'!$B$27 -> 1780934 | D22: =C22-B22 -> -1633806.9
A23: Marge brute | B23: ='Annuel - An 1 à 3'!B29 -> 8227594.4 | C23: =C21-C22 -> 4281575.5 | D23: =C23-B23 -> -3946018.9
A24: Coûts fixes totaux | B24: ='Annuel - An 1 à 3'!B36 -> 4379393.8 | C24: ='Annuel - An 1 à 3'!$B$32+'Annuel - An 1 à 3'!$B$33+'Annuel - An 1 à 3'!$B$34*(1+$B$9)+'Annuel - An 1 à 3'!$B$35 -> 4697736.4 | D24: =C24-B24 -> 318342.53 | E24: Le marketing intègre le surcoût de rétention défini ci-dessus.
A25: EBITDA (résultat opérationnel) | B25: ='Annuel - An 1 à 3'!B38 -> 3848200.5 | C25: =C23-C24 -> -416160.88 | D25: =C25-B25 -> -4264361.4
A26: Marge EBITDA (% du revenu commission) | B26: ='Annuel - An 1 à 3'!B39 -> 0.33053511 | C26: =C25/C21 -> -0.068644986 | D26: =C26-B26 -> -0.3991801
A28: Lecture : même avec un churn chauffeurs, une adoption diaspora et un remplissage nettement dégradés, vérifiez si l'EBITDA reste positif ci-dessus — c'est le test de robustesse du modèle. Modifiez les hypothèses de dégradation en haut de cet onglet pour tester d'autres scénarios.

Sheet Notes & Sources
A1: SIDEBYSIDE — NOTES, SOURCES ET LIMITES DU MODÈLE
A3: Comment utiliser ce fichier
A4: • Toutes les hypothèses modifiables sont dans l'onglet « Hypothèses », sur fond jaune / texte bleu. Change une valeur et tout le reste (Mensuel, Annuel) se recalcule automatiquement.
A5: • L'onglet « Mensuel - An 1 » construit le modèle mois par mois. L'onglet « Annuel - An 1 à 3 » reprend les totaux de l'année 1 et projette les années 2 et 3 à partir de leurs propres hypothèses (croissance du nombre de chauffeurs, trajets/chauffeur, coûts fixes).
A7: Chiffres directement issus du code de l'application (pas des hypothèses)
A8: • Tarifs officiels (Standard 4 500 / Confort 6 500 / VIP 7 500 FCFA) — src/lib/commissionTiers.ts, OFFICIAL_PRICES, axe Douala–Bafoussam.
A9: • Paliers de commission dégressive (15% / 12% / 10% selon le nombre de trajets du chauffeur dans le mois) — src/lib/commissionTiers.ts, COMMISSION_TIERS.
A10: • Remise de 200 FCFA accordée au passager qui paie en mobile money — src/lib/commissionTiers.ts, DIGITAL_PAYMENT_DISCOUNT_XAF.
A12: Chiffres de marché sourcés (contexte, n'entrent pas dans les calculs)
A13: • Population Douala (agglomération) ≈ 4,35M ; Yaoundé ≈ 3,76M ; Bafoussam ≈ 496k — estimations 2025, macrotrends.net et worldpopulationreview.com.
A14: • Le Cameroun compte environ 25M de comptes mobile money actifs, soit 62% des comptes actifs de la zone CEMAC, et le mobile money pèse environ 5% du PIB national — GSMA 2025 / Investir au Cameroun / Financial Afrik, 2025.
A16: Hypothèses — à valider / ajuster en priorité
... A26: • Le scénario de base (onglets Mensuel/Annuel) est central. Un test de sensibilité pessimiste (churn chauffeurs, adoption diaspora et remplissage dégradés) est disponible dans l'onglet « Scénarios ». Pour un scénario optimiste, dupliquer l'onglet Hypothèses et ajuster les taux à la hausse.
